<?xml version="1.0" ?>
<!-- =================================================================================== -->
<!-- |    This document was autogenerated by xacro from allegro_hand.xacro             | -->
<!-- |    EDITING THIS FILE BY HAND IS NOT RECOMMENDED                                 | -->
<!-- =================================================================================== -->
<robot name="ahand" xmlns:xacro="http://www.ros.org/wiki/xacro">
  <!-- ============================================================================= -->
  <!-- friction: not used ... -->
  <!-- END THUMB MACRO -->
  <!-- [[END]] THREE FINGER MACRO -->
  <!-- Base link -->
  <link name="hand_root">
    <origin xyz="0 0 0"/>
  </link>
  <joint name="ahand_root_to_base" type="fixed">
    <parent link="hand_root"/>
    <child link="ahand_palm_link"/>
    <origin xyz="0 0 0.095"/>
  </joint>
  <!-- PALM -->
  <link name="ahand_palm_link">
    <visual>
      <geometry>
        <mesh filename="package://allegro_hand_description/meshes/base_link.STL"/>
      </geometry>
      <origin rpy="0 0 0" xyz="0 0 0 "/>
      <material name="black">
        <color rgba="0.2 0.2 0.2 1"/>
      </material>
    </visual>
    <!--collision>
            <origin rpy="0 0 0" xyz="-0.009300 0 -${palm_link_z/2}"/>
            <geometry>
                <box size="0.0408 0.1130 ${palm_link_z}"/>
            </geometry>
        </collision-->
    <inertial>
      <origin rpy="0 0 0" xyz="0 0 0.0475"/>
      <mass value="0.4154"/>
      <inertia ixx="1e-4" ixy="0.0" ixz="0.0" iyy="1e-4" iyz="0.0" izz="1e-4"/>
    </inertial>
  </link>
  <!-- [LINK 0, 4, 8] -->
  <link name="ahand_link_0">
    <visual>
      <geometry>
        <mesh filename="package://allegro_hand_description/meshes/link_0.0.STL"/>
      </geometry>
      <material name="black"/>
    </visual>
    <collision>
      <geometry>
        <box size="0.0196 0.0275 0.0164"/>
      </geometry>
      <origin rpy="0 0 0" xyz="0 0 0.0082"/>
    </collision>
    <inertial>
      <mass value="0.0119"/>
      <origin rpy="0 0 0" xyz="0 0 0"/>
      <inertia ixx="1.01666658333e-06" ixy="0.0" ixz="0.0" iyy="6.47677333333e-07" iyz="0.0" izz="1.01666658333e-06"/>
    </inertial>
  </link>
  <joint name="ahand_joint_0" type="revolute">
    <axis xyz="0 0 1"/>
    <limit effort="15" lower="-0.47" upper="0.47" velocity="7"/>
    <parent link="ahand_palm_link"/>
    <child link="ahand_link_0"/>
    <origin rpy="-0.08726646255 0 0" xyz="0 0.0435 -0.001542"/>
    <dynamics damping="0.002" friction="0.08"/>
  </joint>
  <!-- [LINK 1, 5, 9] -->
  <link name="ahand_link_1">
    <visual>
      <geometry>
        <mesh filename="package://allegro_hand_description/meshes/link_1.0.STL"/>
      </geometry>
      <material name="black"/>
    </visual>
    <!--collision>
                <geometry>
                    <box size="${links_x} ${links_y} ${link1_z}"/>
                </geometry>
                <origin rpy="0 0 0" xyz="0 0 ${link1_z/2}"/>
            </collision-->
    <inertial>
      <mass value="0.065"/>
      <origin rpy="0 0 0" xyz="0 0 0"/>
      <inertia ixx="7.95654166667e-05" ixy="1.7199e-05" ixz="8.75875e-06" iyy="2.47088833333e-05" iyz="2.413125e-05" izz="7.95654166667e-05"/>
    </inertial>
  </link>
  <joint name="ahand_joint_1" type="revolute">
    <limit effort="15" lower="-0.196" upper="1.61" velocity="7"/>
    <axis xyz="0 1 0"/>
    <parent link="ahand_link_0"/>
    <child link="ahand_link_1"/>
    <origin xyz="0 0 0.0164"/>
    <dynamics damping="0.002" friction="0.08"/>
  </joint>
  <!-- [LINK 2, 6, 10]-->
  <link name="ahand_link_2">
    <visual>
      <geometry>
        <mesh filename="package://allegro_hand_description/meshes/link_2.0.STL"/>
      </geometry>
      <material name="black"/>
    </visual>
    <!--collision>
                <geometry>
                    <box size="${links_x} ${links_y} ${link2_z}"/>
                </geometry>
                <origin rpy="0 0 0" xyz="0 0 ${link2_z/2}"/>
            </collision-->
    <inertial>
      <mass value="0.0355"/>
      <origin rpy="0 0 0" xyz="0 0 0"/>
      <inertia ixx="2.63979183333e-05" ixy="6.67968e-06" ixz="4.783625e-06" iyy="1.34948516667e-05" iyz="9.372e-06" izz="2.63979183333e-05"/>
    </inertial>
  </link>
  <joint name="ahand_joint_2" type="revolute">
    <axis xyz="0 1 0"/>
    <limit effort="15" lower="-0.174" upper="1.709" velocity="7"/>
    <parent link="ahand_link_1"/>
    <child link="ahand_link_2"/>
    <origin xyz="0 0 0.054"/>
    <dynamics damping="0.002" friction="0.08"/>
  </joint>
  <!-- [LINK 3, 7, 11] -->
  <link name="ahand_link_3">
    <visual>
      <geometry>
        <mesh filename="package://allegro_hand_description/meshes/link_3.0.STL"/>
      </geometry>
      <material name="black"/>
    </visual>
    <!--collision>
                <geometry>
                    <box size="${links_x} ${links_y} ${link3_z-fingerTip_r}"/>
                </geometry>
                <origin rpy="0 0 0" xyz="0 0 ${(link3_z-fingerTip_r)/2}"/>
            </collision-->
    <inertial>
      <mass value="0.0096"/>
      <origin rpy="0 0 0" xyz="0 0 0"/>
      <inertia ixx="4.701248e-06" ixy="1.255968e-06" ixz="1.2936e-06" iyy="3.649312e-06" iyz="1.7622e-06" izz="4.701248e-06"/>
    </inertial>
  </link>
  <joint name="ahand_joint_3" type="revolute">
    <axis xyz="0 1 0"/>
    <limit effort="15" lower="-0.227" upper="1.618" velocity="7"/>
    <parent link="ahand_link_2"/>
    <child link="ahand_link_3"/>
    <origin xyz="0 0 0.0384"/>
    <dynamics damping="0.002" friction="0.08"/>
  </joint>
  <!-- [FINGER TIP] -->
  <link name="ahand_link_3_tip">
    <visual>
      <geometry>
        <mesh filename="package://allegro_hand_description/meshes/link_3.0_tip.STL"/>
      </geometry>
      <material name="white">
        <color rgba=".9 .9 .9 1"/>
      </material>
    </visual>
    <!--collision>
                <geometry>
                    <sphere radius="${fingerTip_r}"/>
                </geometry>
            </collision-->
    <inertial>
      <mass value="0.0168"/>
      <origin rpy="0 0 0" xyz="0 0 0"/>
      <inertia ixx="9.68e-07" ixy="0" ixz="0" iyy="9.68e-07" iyz="0" izz="9.68e-07"/>
    </inertial>
  </link>
  <joint name="ahand_joint_3_tip" type="fixed">
    <parent link="ahand_link_3"/>
    <child link="ahand_link_3_tip"/>
    <origin rpy="0 0 0" xyz="0 0 0.0267"/>
  </joint>
  <!-- [LINK 0, 4, 8] -->
  <link name="ahand_link_4">
    <visual>
      <geometry>
        <mesh filename="package://allegro_hand_description/meshes/link_0.0.STL"/>
      </geometry>
      <material name="black"/>
    </visual>
    <collision>
      <geometry>
        <box size="0.0196 0.0275 0.0164"/>
      </geometry>
      <origin rpy="0 0 0" xyz="0 0 0.0082"/>
    </collision>
    <inertial>
      <mass value="0.0119"/>
      <origin rpy="0 0 0" xyz="0 0 0"/>
      <inertia ixx="1.01666658333e-06" ixy="0.0" ixz="0.0" iyy="6.47677333333e-07" iyz="0.0" izz="1.01666658333e-06"/>
    </inertial>
  </link>
  <joint name="ahand_joint_4" type="revolute">
    <axis xyz="0 0 1"/>
    <limit effort="15" lower="-0.47" upper="0.47" velocity="7"/>
    <parent link="ahand_palm_link"/>
    <child link="ahand_link_4"/>
    <origin rpy="0.0 0 0" xyz="0 0 0.0007"/>
    <dynamics damping="0.002" friction="0.08"/>
  </joint>
  <!-- [LINK 1, 5, 9] -->
  <link name="ahand_link_5">
    <visual>
      <geometry>
        <mesh filename="package://allegro_hand_description/meshes/link_1.0.STL"/>
      </geometry>
      <material name="black"/>
    </visual>
    <!--collision>
                <geometry>
                    <box size="${links_x} ${links_y} ${link1_z}"/>
                </geometry>
                <origin rpy="0 0 0" xyz="0 0 ${link1_z/2}"/>
            </collision-->
    <inertial>
      <mass value="0.065"/>
      <origin rpy="0 0 0" xyz="0 0 0"/>
      <inertia ixx="7.95654166667e-05" ixy="1.7199e-05" ixz="8.75875e-06" iyy="2.47088833333e-05" iyz="2.413125e-05" izz="7.95654166667e-05"/>
    </inertial>
  </link>
  <joint name="ahand_joint_5" type="revolute">
    <limit effort="15" lower="-0.196" upper="1.61" velocity="7"/>
    <axis xyz="0 1 0"/>
    <parent link="ahand_link_4"/>
    <child link="ahand_link_5"/>
    <origin xyz="0 0 0.0164"/>
    <dynamics damping="0.002" friction="0.08"/>
  </joint>
  <!-- [LINK 2, 6, 10]-->
  <link name="ahand_link_6">
    <visual>
      <geometry>
        <mesh filename="package://allegro_hand_description/meshes/link_2.0.STL"/>
      </geometry>
      <material name="black"/>
    </visual>
    <!--collision>
                <geometry>
                    <box size="${links_x} ${links_y} ${link2_z}"/>
                </geometry>
                <origin rpy="0 0 0" xyz="0 0 ${link2_z/2}"/>
            </collision-->
    <inertial>
      <mass value="0.0355"/>
      <origin rpy="0 0 0" xyz="0 0 0"/>
      <inertia ixx="2.63979183333e-05" ixy="6.67968e-06" ixz="4.783625e-06" iyy="1.34948516667e-05" iyz="9.372e-06" izz="2.63979183333e-05"/>
    </inertial>
  </link>
  <joint name="ahand_joint_6" type="revolute">
    <axis xyz="0 1 0"/>
    <limit effort="15" lower="-0.174" upper="1.709" velocity="7"/>
    <parent link="ahand_link_5"/>
    <child link="ahand_link_6"/>
    <origin xyz="0 0 0.054"/>
    <dynamics damping="0.002" friction="0.08"/>
  </joint>
  <!-- [LINK 3, 7, 11] -->
  <link name="ahand_link_7">
    <visual>
      <geometry>
        <mesh filename="package://allegro_hand_description/meshes/link_3.0.STL"/>
      </geometry>
      <material name="black"/>
    </visual>
    <!--collision>
                <geometry>
                    <box size="${links_x} ${links_y} ${link3_z-fingerTip_r}"/>
                </geometry>
                <origin rpy="0 0 0" xyz="0 0 ${(link3_z-fingerTip_r)/2}"/>
            </collision-->
    <inertial>
      <mass value="0.0096"/>
      <origin rpy="0 0 0" xyz="0 0 0"/>
      <inertia ixx="4.701248e-06" ixy="1.255968e-06" ixz="1.2936e-06" iyy="3.649312e-06" iyz="1.7622e-06" izz="4.701248e-06"/>
    </inertial>
  </link>
  <joint name="ahand_joint_7" type="revolute">
    <axis xyz="0 1 0"/>
    <limit effort="15" lower="-0.227" upper="1.618" velocity="7"/>
    <parent link="ahand_link_6"/>
    <child link="ahand_link_7"/>
    <origin xyz="0 0 0.0384"/>
    <dynamics damping="0.002" friction="0.08"/>
  </joint>
  <!-- [FINGER TIP] -->
  <link name="ahand_link_7_tip">
    <visual>
      <geometry>
        <mesh filename="package://allegro_hand_description/meshes/link_3.0_tip.STL"/>
      </geometry>
      <material name="white">
        <color rgba=".9 .9 .9 1"/>
      </material>
    </visual>
    <!--collision>
                <geometry>
                    <sphere radius="${fingerTip_r}"/>
                </geometry>
            </collision-->
    <inertial>
      <mass value="0.0168"/>
      <origin rpy="0 0 0" xyz="0 0 0"/>
      <inertia ixx="9.68e-07" ixy="0" ixz="0" iyy="9.68e-07" iyz="0" izz="9.68e-07"/>
    </inertial>
  </link>
  <joint name="ahand_joint_7_tip" type="fixed">
    <parent link="ahand_link_7"/>
    <child link="ahand_link_7_tip"/>
    <origin rpy="0 0 0" xyz="0 0 0.0267"/>
  </joint>
  <!-- [LINK 0, 4, 8] -->
  <link name="ahand_link_8">
    <visual>
      <geometry>
        <mesh filename="package://allegro_hand_description/meshes/link_0.0.STL"/>
      </geometry>
      <material name="black"/>
    </visual>
    <collision>
      <geometry>
        <box size="0.0196 0.0275 0.0164"/>
      </geometry>
      <origin rpy="0 0 0" xyz="0 0 0.0082"/>
    </collision>
    <inertial>
      <mass value="0.0119"/>
      <origin rpy="0 0 0" xyz="0 0 0"/>
      <inertia ixx="1.01666658333e-06" ixy="0.0" ixz="0.0" iyy="6.47677333333e-07" iyz="0.0" izz="1.01666658333e-06"/>
    </inertial>
  </link>
  <joint name="ahand_joint_8" type="revolute">
    <axis xyz="0 0 1"/>
    <limit effort="15" lower="-0.47" upper="0.47" velocity="7"/>
    <parent link="ahand_palm_link"/>
    <child link="ahand_link_8"/>
    <origin rpy="0.08726646255 0 0" xyz="0 -0.0435 -0.001542"/>
    <dynamics damping="0.002" friction="0.08"/>
  </joint>
  <!-- [LINK 1, 5, 9] -->
  <link name="ahand_link_9">
    <visual>
      <geometry>
        <mesh filename="package://allegro_hand_description/meshes/link_1.0.STL"/>
      </geometry>
      <material name="black"/>
    </visual>
    <!--collision>
                <geometry>
                    <box size="${links_x} ${links_y} ${link1_z}"/>
                </geometry>
                <origin rpy="0 0 0" xyz="0 0 ${link1_z/2}"/>
            </collision-->
    <inertial>
      <mass value="0.065"/>
      <origin rpy="0 0 0" xyz="0 0 0"/>
      <inertia ixx="7.95654166667e-05" ixy="1.7199e-05" ixz="8.75875e-06" iyy="2.47088833333e-05" iyz="2.413125e-05" izz="7.95654166667e-05"/>
    </inertial>
  </link>
  <joint name="ahand_joint_9" type="revolute">
    <limit effort="15" lower="-0.196" upper="1.61" velocity="7"/>
    <axis xyz="0 1 0"/>
    <parent link="ahand_link_8"/>
    <child link="ahand_link_9"/>
    <origin xyz="0 0 0.0164"/>
    <dynamics damping="0.002" friction="0.08"/>
  </joint>
  <!-- [LINK 2, 6, 10]-->
  <link name="ahand_link_10">
    <visual>
      <geometry>
        <mesh filename="package://allegro_hand_description/meshes/link_2.0.STL"/>
      </geometry>
      <material name="black"/>
    </visual>
    <!--collision>
                <geometry>
                    <box size="${links_x} ${links_y} ${link2_z}"/>
                </geometry>
                <origin rpy="0 0 0" xyz="0 0 ${link2_z/2}"/>
            </collision-->
    <inertial>
      <mass value="0.0355"/>
      <origin rpy="0 0 0" xyz="0 0 0"/>
      <inertia ixx="2.63979183333e-05" ixy="6.67968e-06" ixz="4.783625e-06" iyy="1.34948516667e-05" iyz="9.372e-06" izz="2.63979183333e-05"/>
    </inertial>
  </link>
  <joint name="ahand_joint_10" type="revolute">
    <axis xyz="0 1 0"/>
    <limit effort="15" lower="-0.174" upper="1.709" velocity="7"/>
    <parent link="ahand_link_9"/>
    <child link="ahand_link_10"/>
    <origin xyz="0 0 0.054"/>
    <dynamics damping="0.002" friction="0.08"/>
  </joint>
  <!-- [LINK 3, 7, 11] -->
  <link name="ahand_link_11">
    <visual>
      <geometry>
        <mesh filename="package://allegro_hand_description/meshes/link_3.0.STL"/>
      </geometry>
      <material name="black"/>
    </visual>
    <!--collision>
                <geometry>
                    <box size="${links_x} ${links_y} ${link3_z-fingerTip_r}"/>
                </geometry>
                <origin rpy="0 0 0" xyz="0 0 ${(link3_z-fingerTip_r)/2}"/>
            </collision-->
    <inertial>
      <mass value="0.0096"/>
      <origin rpy="0 0 0" xyz="0 0 0"/>
      <inertia ixx="4.701248e-06" ixy="1.255968e-06" ixz="1.2936e-06" iyy="3.649312e-06" iyz="1.7622e-06" izz="4.701248e-06"/>
    </inertial>
  </link>
  <joint name="ahand_joint_11" type="revolute">
    <axis xyz="0 1 0"/>
    <limit effort="15" lower="-0.227" upper="1.618" velocity="7"/>
    <parent link="ahand_link_10"/>
    <child link="ahand_link_11"/>
    <origin xyz="0 0 0.0384"/>
    <dynamics damping="0.002" friction="0.08"/>
  </joint>
  <!-- [FINGER TIP] -->
  <link name="ahand_link_11_tip">
    <visual>
      <geometry>
        <mesh filename="package://allegro_hand_description/meshes/link_3.0_tip.STL"/>
      </geometry>
      <material name="white">
        <color rgba=".9 .9 .9 1"/>
      </material>
    </visual>
    <!--collision>
                <geometry>
                    <sphere radius="${fingerTip_r}"/>
                </geometry>
            </collision-->
    <inertial>
      <mass value="0.0168"/>
      <origin rpy="0 0 0" xyz="0 0 0"/>
      <inertia ixx="9.68e-07" ixy="0" ixz="0" iyy="9.68e-07" iyz="0" izz="9.68e-07"/>
    </inertial>
  </link>
  <joint name="ahand_joint_11_tip" type="fixed">
    <parent link="ahand_link_11"/>
    <child link="ahand_link_11_tip"/>
    <origin rpy="0 0 0" xyz="0 0 0.0267"/>
  </joint>
  <!-- [LINK 12] -->
  <link name="ahand_link_12">
    <visual>
      <geometry>
        <mesh filename="package://allegro_hand_description/meshes/link_12.0_right.STL"/>
      </geometry>
      <material name="black">
        <color rgba=".2 .2 .2 1"/>
      </material>
      <origin rpy="3.1415926518 0 0" xyz="0 0 0"/>
    </visual>
    <!--collision>
                <geometry>
                    <box size="${link0_t_x} ${link0_t_y} ${link0_t_z}"/>
                </geometry>
                <origin rpy="0 0 0" xyz="${-0.0358/2+0.0} ${.018/2} ${.029/2}"/>
            </collision-->
    <inertial>
      <mass value="0.0176"/>
      <origin rpy="0 0 0" xyz="0 0 0"/>
      <inertia ixx="1.89273333333e-5" ixy="7.16716e-06" ixz="5.35568e-06" iyy="1.43008213333e-05" iyz="6.8068e-06" izz="1.89273333333e-05"/>
    </inertial>
  </link>
  <joint name="ahand_joint_12" type="revolute">
    <axis xyz="-1 0 0"/>
    <limit effort="15" lower="0.263" upper="1.396" velocity="7"/>
    <parent link="ahand_palm_link"/>
    <child link="ahand_link_12"/>
    <origin rpy="0 -1.65806278845 -1.5707963259" xyz="-0.0182 0.019333 -0.045987"/>
    <dynamics damping="0.002" friction="0.08"/>
  </joint>
  <!-- [LINK 13] -->
  <link name="ahand_link_13">
    <visual>
      <geometry>
        <mesh filename="package://allegro_hand_description/meshes/link_13.0.STL"/>
      </geometry>
      <material name="black">
        <color rgba=".2 .2 .2 1"/>
      </material>
    </visual>
    <!--collision>
                <geometry>
                    <box size="${links_x} ${links_y} ${link1_t_z}"/>
                </geometry>
                <origin rpy="0 0 0" xyz="0 0 ${link1_t_z/2}"/>
            </collision-->
    <inertial>
      <mass value="0.0119"/>
      <origin rpy="0 0 0" xyz="0 0 0"/>
      <inertia ixx="4.24250866667e-06" ixy="1.032087e-06" ixz="1.603525e-06" iyy="4.52362633333e-06" iyz="1.44808125e-06" izz="4.24250866667e-06"/>
    </inertial>
  </link>
  <joint name="ahand_joint_13" type="revolute">
    <axis xyz="0 0 1"/>
    <limit effort="15" lower="-0.105" upper="1.163" velocity="7"/>
    <parent link="ahand_link_12"/>
    <child link="ahand_link_13"/>
    <origin xyz="-0.027 0.005 0.0399"/>
    <dynamics damping="0.002" friction="0.08"/>
  </joint>
  <!-- [LINK 14] -->
  <link name="ahand_link_14">
    <visual>
      <geometry>
        <mesh filename="package://allegro_hand_description/meshes/link_14.0.STL"/>
      </geometry>
      <material name="black">
                </material>
    </visual>
    <!--collision>
                <geometry>
                    <box size="${links_x} ${links_y} ${link2_t_z}"/>
                </geometry>
                <origin rpy="0 0 0" xyz="0 0 ${link2_t_z/2}"/>
            </collision-->
    <inertial>
      <mass value="0.038"/>
      <origin rpy="0 0 0" xyz="0 0 0"/>
      <inertia ixx="4.30439933333e-05" ixy="9.57068e-06" ixz="5.1205e-06" iyy="1.44451933333e-05" iyz="1.342825e-05" izz="4.30439933333e-05"/>
    </inertial>
  </link>
  <joint name="ahand_joint_14" type="revolute">
    <axis xyz="0 1 0"/>
    <limit effort="15" lower="-0.189" upper="1.644" velocity="7"/>
    <parent link="ahand_link_13"/>
    <child link="ahand_link_14"/>
    <origin xyz="0 0 0.0177"/>
    <dynamics damping="0.002" friction="0.08"/>
  </joint>
  <!-- [LINK 15] -->
  <link name="ahand_link_15">
    <visual>
      <geometry>
        <mesh filename="package://allegro_hand_description/meshes/link_15.0.STL"/>
      </geometry>
      <material name="black">
                </material>
    </visual>
    <!--collision>
                <geometry>
                    <box size="${links_x} ${links_y} ${link3_t_z-fingerTip_r}"/>
                </geometry>
                <origin rpy="0 0 0" xyz="0 0 ${(link3_t_z-fingerTip_r)/2}"/>
            </collision-->
    <inertial>
      <mass value="0.0388"/>
      <origin rpy="0 0 0" xyz="0 0 0"/>
      <inertia ixx="3.29223173333e-05" ixy="8.042076e-06" ixz="5.2283e-06" iyy="1.47493026667e-5" iyz="1.1283525e-5" izz="3.29223173333e-05"/>
    </inertial>
  </link>
  <joint name="ahand_joint_15" type="revolute">
    <axis xyz="0 1 0"/>
    <limit effort="15" lower="-0.162" upper="1.719" velocity="7"/>
    <parent link="ahand_link_14"/>
    <child link="ahand_link_15"/>
    <origin xyz="0 0 0.0514"/>
    <dynamics damping="0.002" friction="0.08"/>
  </joint>
  <!-- [FINGER TIP] -->
  <link name="ahand_link_15_tip">
    <visual>
      <geometry>
        <mesh filename="package://allegro_hand_description/meshes/link_15.0_tip.STL"/>
      </geometry>
      <material name="white">
        <color rgba=".9 .9 .9 1"/>
      </material>
    </visual>
    <!--collision>
                <geometry>
                    <sphere radius="${fingerTip_r}"/>
                </geometry>
                <origin rpy="0 0 0" xyz="0 0 0"/>
            </collision-->
    <inertial>
      <mass value="0.0168"/>
      <origin rpy="0 0 0" xyz="0 0 0"/>
      <inertia ixx="9.68e-07" ixy="0" ixz="0" iyy="9.68e-07" iyz="0" izz="9.68e-07"/>
    </inertial>
  </link>
  <joint name="ahand_joint_15_tip" type="fixed">
    <parent link="ahand_link_15"/>
    <child link="ahand_link_15_tip"/>
    <origin rpy="0 0 0" xyz="0 0 0.0423"/>
  </joint>
  <!-- ============================================================================= -->
  <gazebo>
    <plugin filename="libahand_hw_gazebo_plugin.so" name="ahand_hw_sim">
      <robotNamespace>ahand</robotNamespace>
    </plugin>
  </gazebo>
  <gazebo reference="ahand_link_0">
    <gravity>true</gravity>
    <selfCollide>false</selfCollide>
  </gazebo>
  <gazebo reference="ahand_link_1">
    <gravity>true</gravity>
    <selfCollide>false</selfCollide>
  </gazebo>
  <gazebo reference="ahand_link_2">
    <gravity>true</gravity>
    <selfCollide>false</selfCollide>
  </gazebo>
  <gazebo reference="ahand_link_3">
    <gravity>true</gravity>
    <selfCollide>false</selfCollide>
  </gazebo>
  <gazebo reference="ahand_link_4">
    <gravity>true</gravity>
    <selfCollide>false</selfCollide>
  </gazebo>
  <gazebo reference="ahand_link_5">
    <gravity>true</gravity>
    <selfCollide>false</selfCollide>
  </gazebo>
  <gazebo reference="ahand_link_6">
    <gravity>true</gravity>
    <selfCollide>false</selfCollide>
  </gazebo>
  <gazebo reference="ahand_link_7">
    <gravity>true</gravity>
    <selfCollide>false</selfCollide>
  </gazebo>
  <gazebo reference="ahand_link_8">
    <gravity>true</gravity>
    <selfCollide>false</selfCollide>
  </gazebo>
  <gazebo reference="ahand_link_9">
    <gravity>true</gravity>
    <selfCollide>false</selfCollide>
  </gazebo>
  <gazebo reference="ahand_link_10">
    <gravity>true</gravity>
    <selfCollide>false</selfCollide>
  </gazebo>
  <gazebo reference="ahand_link_11">
    <gravity>true</gravity>
    <selfCollide>false</selfCollide>
  </gazebo>
  <gazebo reference="ahand_link_12">
    <gravity>true</gravity>
    <selfCollide>false</selfCollide>
  </gazebo>
  <gazebo reference="ahand_link_13">
    <gravity>true</gravity>
    <selfCollide>false</selfCollide>
  </gazebo>
  <gazebo reference="ahand_link_14">
    <gravity>true</gravity>
    <selfCollide>false</selfCollide>
  </gazebo>
  <gazebo reference="ahand_link_15">
    <gravity>true</gravity>
    <selfCollide>false</selfCollide>
  </gazebo>
  <transmission name="ahand_0_trans">
    <type>transmission_interface/SimpleTransmission</type>
    <joint name="ahand_joint_0">
      <hardwareInterface>hardware_interface/EffortJointInterface</hardwareInterface>
    </joint>
    <actuator name="ahand_0_motor">
      <mechanicalReduction>1</mechanicalReduction>
    </actuator>
  </transmission>
  <transmission name="ahand_1_trans">
    <type>transmission_interface/SimpleTransmission</type>
    <joint name="ahand_joint_1">
      <hardwareInterface>hardware_interface/EffortJointInterface</hardwareInterface>
    </joint>
    <actuator name="ahand_1_motor">
      <mechanicalReduction>1</mechanicalReduction>
    </actuator>
  </transmission>
  <transmission name="ahand_2_trans">
    <type>transmission_interface/SimpleTransmission</type>
    <joint name="ahand_joint_2">
      <hardwareInterface>hardware_interface/EffortJointInterface</hardwareInterface>
    </joint>
    <actuator name="ahand_2_motor">
      <mechanicalReduction>1</mechanicalReduction>
    </actuator>
  </transmission>
  <transmission name="ahand_3_trans">
    <type>transmission_interface/SimpleTransmission</type>
    <joint name="ahand_joint_3">
      <hardwareInterface>hardware_interface/EffortJointInterface</hardwareInterface>
    </joint>
    <actuator name="ahand_3_motor">
      <mechanicalReduction>1</mechanicalReduction>
    </actuator>
  </transmission>
  <transmission name="ahand_4_trans">
    <type>transmission_interface/SimpleTransmission</type>
    <joint name="ahand_joint_4">
      <hardwareInterface>hardware_interface/EffortJointInterface</hardwareInterface>
    </joint>
    <actuator name="ahand_4_motor">
      <mechanicalReduction>1</mechanicalReduction>
    </actuator>
  </transmission>
  <transmission name="ahand_5_trans">
    <type>transmission_interface/SimpleTransmission</type>
    <joint name="ahand_joint_5">
      <hardwareInterface>hardware_interface/EffortJointInterface</hardwareInterface>
    </joint>
    <actuator name="ahand_5_motor">
      <mechanicalReduction>1</mechanicalReduction>
    </actuator>
  </transmission>
  <transmission name="ahand_6_trans">
    <type>transmission_interface/SimpleTransmission</type>
    <joint name="ahand_joint_6">
      <hardwareInterface>hardware_interface/EffortJointInterface</hardwareInterface>
    </joint>
    <actuator name="ahand_6_motor">
      <mechanicalReduction>1</mechanicalReduction>
    </actuator>
  </transmission>
  <transmission name="ahand_7_trans">
    <type>transmission_interface/SimpleTransmission</type>
    <joint name="ahand_joint_7">
      <hardwareInterface>hardware_interface/EffortJointInterface</hardwareInterface>
    </joint>
    <actuator name="ahand_7_motor">
      <mechanicalReduction>1</mechanicalReduction>
    </actuator>
  </transmission>
  <transmission name="ahand_8_trans">
    <type>transmission_interface/SimpleTransmission</type>
    <joint name="ahand_joint_8">
      <hardwareInterface>hardware_interface/EffortJointInterface</hardwareInterface>
    </joint>
    <actuator name="ahand_8_motor">
      <mechanicalReduction>1</mechanicalReduction>
    </actuator>
  </transmission>
  <transmission name="ahand_9_trans">
    <type>transmission_interface/SimpleTransmission</type>
    <joint name="ahand_joint_9">
      <hardwareInterface>hardware_interface/EffortJointInterface</hardwareInterface>
    </joint>
    <actuator name="ahand_9_motor">
      <mechanicalReduction>1</mechanicalReduction>
    </actuator>
  </transmission>
  <transmission name="ahand_10_trans">
    <type>transmission_interface/SimpleTransmission</type>
    <joint name="ahand_joint_10">
      <hardwareInterface>hardware_interface/EffortJointInterface</hardwareInterface>
    </joint>
    <actuator name="ahand_10_motor">
      <mechanicalReduction>1</mechanicalReduction>
    </actuator>
  </transmission>
  <transmission name="ahand_11_trans">
    <type>transmission_interface/SimpleTransmission</type>
    <joint name="ahand_joint_11">
      <hardwareInterface>hardware_interface/EffortJointInterface</hardwareInterface>
    </joint>
    <actuator name="ahand_11_motor">
      <mechanicalReduction>1</mechanicalReduction>
    </actuator>
  </transmission>
  <transmission name="ahand_12_trans">
    <type>transmission_interface/SimpleTransmission</type>
    <joint name="ahand_joint_12">
      <hardwareInterface>hardware_interface/EffortJointInterface</hardwareInterface>
    </joint>
    <actuator name="ahand_12_motor">
      <mechanicalReduction>1</mechanicalReduction>
    </actuator>
  </transmission>
  <transmission name="ahand_13_trans">
    <type>transmission_interface/SimpleTransmission</type>
    <joint name="ahand_joint_13">
      <hardwareInterface>hardware_interface/EffortJointInterface</hardwareInterface>
    </joint>
    <actuator name="ahand_13_motor">
      <mechanicalReduction>1</mechanicalReduction>
    </actuator>
  </transmission>
  <transmission name="ahand_14_trans">
    <type>transmission_interface/SimpleTransmission</type>
    <joint name="ahand_joint_14">
      <hardwareInterface>hardware_interface/EffortJointInterface</hardwareInterface>
    </joint>
    <actuator name="ahand_14_motor">
      <mechanicalReduction>1</mechanicalReduction>
    </actuator>
  </transmission>
  <transmission name="ahand_15_trans">
    <type>transmission_interface/SimpleTransmission</type>
    <joint name="ahand_joint_15">
      <hardwareInterface>hardware_interface/EffortJointInterface</hardwareInterface>
    </joint>
    <actuator name="ahand_15_motor">
      <mechanicalReduction>1</mechanicalReduction>
    </actuator>
  </transmission>
  <!--link name="world"/-->
  <!--xacro:ahand prefix="ahand" parent_link="world" xyz="1.0 0 0.15" rpy="0 0 0" left="1"/-->
</robot>

